Traceback (most recent call last):
  File "retrain.py", line 179, in main
    validation_data=validation_generator,validation_steps= math.ceil(val_sample_size / batch_size),)
  File "C:\Users\AppiTech\miniconda3\envs\conda_env\lib\site-packages\tensorflow_core\python\keras\engine\training.py", line 819, in fit
    use_multiprocessing=use_multiprocessing)
  File "C:\Users\AppiTech\miniconda3\envs\conda_env\lib\site-packages\tensorflow_core\python\keras\engine\training_v2.py", line 342, in fit
    total_epochs=epochs)
  File "C:\Users\AppiTech\miniconda3\envs\conda_env\lib\site-packages\tensorflow_core\python\keras\engine\training_v2.py", line 128, in run_one_epoch
    batch_outs = execution_function(iterator)
  File "C:\Users\AppiTech\miniconda3\envs\conda_env\lib\site-packages\tensorflow_core\python\keras\engine\training_v2_utils.py", line 98, in execution_function
    distributed_function(input_fn))
  File "C:\Users\AppiTech\miniconda3\envs\conda_env\lib\site-packages\tensorflow_core\python\eager\def_function.py", line 568, in __call__
    result = self._call(*args, **kwds)
  File "C:\Users\AppiTech\miniconda3\envs\conda_env\lib\site-packages\tensorflow_core\python\eager\def_function.py", line 599, in _call
    return self._stateless_fn(*args, **kwds)  # pylint: disable=not-callable
  File "C:\Users\AppiTech\miniconda3\envs\conda_env\lib\site-packages\tensorflow_core\python\eager\function.py", line 2363, in __call__
    return graph_function._filtered_call(args, kwargs)  # pylint: disable=protected-access
  File "C:\Users\AppiTech\miniconda3\envs\conda_env\lib\site-packages\tensorflow_core\python\eager\function.py", line 1611, in _filtered_call
    self.captured_inputs)
  File "C:\Users\AppiTech\miniconda3\envs\conda_env\lib\site-packages\tensorflow_core\python\eager\function.py", line 1692, in _call_flat
    ctx, args, cancellation_manager=cancellation_manager))
  File "C:\Users\AppiTech\miniconda3\envs\conda_env\lib\site-packages\tensorflow_core\python\eager\function.py", line 545, in call
    ctx=ctx)
  File "C:\Users\AppiTech\miniconda3\envs\conda_env\lib\site-packages\tensorflow_core\python\eager\execute.py", line 67, in quick_execute
    six.raise_from(core._status_to_exception(e.code, message), None)
  File "<string>", line 3, in raise_from
tensorflow.python.framework.errors_impl.InvalidArgumentError: 2 root error(s) found.
  (0) Invalid argument:  assertion failed: [predictions must be >= 0] [Condition x >= y did not hold element-wise:] [x (model_1/conv2d_7/truediv:0) = ] [[[[0.00203790353 0.944078 0.0538841151]]]...] [y (metrics/precision/Cast_2/x:0) = ] [0]
         [[{{node metrics/precision/assert_greater_equal/Assert/AssertGuard/else/_1/Assert}}]]
         [[metrics/precision/assert_less_equal/Assert/AssertGuard/pivot_f/_13/_43]]
  (1) Invalid argument:  assertion failed: [predictions must be >= 0] [Condition x >= y did not hold element-wise:] [x (model_1/conv2d_7/truediv:0) = ] [[[[0.00203790353 0.944078 0.0538841151]]]...] [y (metrics/precision/Cast_2/x:0) = ] [0]
         [[{{node metrics/precision/assert_greater_equal/Assert/AssertGuard/else/_1/Assert}}]]
0 successful operations.
0 derived errors ignored. [Op:__inference_distributed_function_1875]